SampleOutput/sample_vwap_4.txt
XBUY: 16.5865
NRGX: 20.4506
CFG-D: 25.0922
ZYNE: 5.0501
ZYME: 15.2326
ZXZZT: 6.6666
ZVZZT: 9.9881
ZUO: 21.2175
ZUMZ: 24.933
ZTS: 85.2601
ZTR: 9.7628
ZTO: 16.9378
ZSL: 35.2315
ZSAN: 2.1374
ZS: 45.4279
ZROZ: 74.7999
ZOM: 0.9174
ZNH: 32.4384
ZNGA: 4.4837
ZN: 0.4815
ZMLP: 9.0533
ZLAB: 26.8863
ZKIN: 1.5452
ZJZZT: 6.6666
ZIXI: 7.5071
ZIV: 66.5133
ZIOP: 2.0366
ZIONW: 10.7799
ZION: 48.2952
ZGNX: 41.6321
ZG: 32.8284
ZFGN: 4.2286
ZF: 8.7571
ZEUS: 18.6017
ZEN: 65.2807
ZEAL: 14.3166
ZDGE: 1.2933
ZBRA: 170.6993
ZBIO: 15.9775
ZBH: 107.2358
ZB-G: 26.84
ZAYO: 26.6913
ZAGG: 11.17
Z: 33.0782
YYY: 17.251
YY: 67.182
YVR: 1.5666
YUMC: 35.7619
YUMA: 0.1137
YUM: 93.2625
YTRA: 5.1016
YTEN: 0.7225
YRIV: 2.0734
YRD: 10.9692
YRCW: 5.7502
YPF: 15.7118
YORW: 31.5382
YOGA: 0.489
YNDX: 32.8133
YMLP: 19.35
YMLI: 8.2466
YMAB: 19.6625
YLCO: 8.1399
YINN: 21.3291
YIN: 6.9419
YI: 8.6272
YGYI: 7.3397
YEXT: 14.9492
YETI: 16.7317
YELP: 36.0904
YCS: 49.4224
YANG: 52.7733
Y: 622.0243
XYL: 70.5313
XXII: 2.261
XWEB: 84.9333
XTN: 39.6432
XTL: 65.0421
XT: 35.5905
XSW: 76.147
XSPA: 0.1827
XSOE: 18.4399
XSLV: 45.5848
XSD: 68.6643
XRX: 27.7881
XRT: 43.9501
XRLV: 22.7399
XRAY: 41.0761
XPP: 65.3692
XPO: 61.5101
XPL: 0.184
XPH: 38.4567
XPER: 21.018
XOP: 30.4955
XONE: 8.3261
XON: 7.4376
XOMA: 11.9741
XOM: 71.8531
XOG: 4.0529
XNTK: 57.0587
XNET: 3.4055
XNCR: 32.4674
XMLV: 39.4181
XME: 29.9505
XLY: 106.8124
XLV: 88.7644
XLU: 53.4286
XLRN: 39.9164
XLRE: 33.8864
XLP: 52.2069
XLNX: 111.1107
XLK: 65.4843
XLI: 70.7331
XLG: 168.4141
XLF: 25.8425
XLE: 62.8592
XLC: 43.7288
XLB: 53.8511
XKST: 26.5
XITK: 92.5633
XIN: 4.7615
XHS: 45.6399
XHR: 18.6439
XHE: 71.3375
XHB: 35.5706
XGTI: 0.3699
XFLT: 5.6599
XES: 10.8731
XERS: 15.0003
XENT: 28.8659
XENE: 7.8976
XELB: 0.8133
XELA: 3.6045
XEL: 50.8956
XEC: 75.7405
XCEM: 17.2466
XBIT: 6.44
XBIO: 2.1394
XBI: 80.4432
XAR: 88.2831
XAN: 10.5108
X: 22.1016
WYY: 0.4399
WYNN: 119.411
WYND: 42.268
WY: 26.1039
WWW: 33.8865
WWR: 0.1415
WWE: 81.9033
WWD: 85.7975
WVVIP: 3.0799
WVVI: 4.7066
WVFC: 9.6733
WVE: 35.4072
WUBA: 61.0916
WU: 18.2424
WTW: 32.1195
WTTR: 8.5659
WTS: 73.0848
WTRH: 12.1552
WTR: 34.2466
WTM: 893.2353
WTIU: 13.9254
WTID: 9.605
WTI: 5.0614
WTFCM: 18.5599
WTFC: 72.6169
WTER: 3.5016
WTBA: 21.6241
WSTL: 1.8328
WST: 105.5298
WSR: 14.3084
WSO: 146.3847
WSM: 52.4068
WSFS: 41.9928
WSC: 10.1344
WSBF: 16.6875
WSBC: 41.52
WRTC: 2.7839
WRN: 0.7176
WRLSR: 0.2534
WRLS: 10.2
WRLD: 109.5992
WRK: 41.2881
WRI: 28.4298
WRE: 25.0932
WRD: 17.1236
WRB-E: 24.3308
WRB-D: 16.3299
WRB-C: 25.0733
WRB-B: 24.5272
WRB: 77.0347
WPX: 12.2544
WPS: 35.7751
WPRT: 1.4826
WPP: 57.7282
WPM: 20.2068
WPG-H: 10.4999
WPG: 5.7426
WPC: 73.9659
WP: 83.4927
WOW: 7.2501
WOR: 36.6214
WOOD: 66.0202
WNS: 48.9292
WNEB: 9.3107
WNC: 13.9291
WMT: 94.9535
WMS: 25.0651
WMK: 47.7504
WMGI: 29.6821
WMC: 9.5659
WMB: 26.8601
WM: 94.4622
WLTW: 159.6995
WLL: 28.5987
WLKP: 23.3877
WLK: 75.9852
WLH: 12.3231
WLFC: 37.8
WLDN: 31.4597
WKHS: 0.8848
WK: 39.1573
WIX: 105.4449
WIW: 10.5133
WIT: 5.4781
WISA: 2.0266
WIRE: 52.5607
WIP: 35.9197
WINS: 23.7696
WING: 66.2551
WINA: 152.8709
WIN: 2.8577
WIFI: 22.7481
WIA: 10.91
WHR: 130.8804
WHLRW: 0.0066
WHLRP: 10.25
WHLR: 1.6604
WHLM: 3.4999
WHG: 36.0207
WHF: 13.4217
WHD: 32.456
WH: 49.6046
WGP: 32.5784
WGO: 29.3397
WFT: 0.6383
WFHY: 32.9333
WFE-A: 25.72
WFC-Y: 16.6666
WFC-X: 22.3759
WFC-W: 23.5535
WFC-V: 25.8114
WFC-T: 17.1933
WFC-R: 18.4742
WFC-Q: 25.3742
WFC-P: 15.6266
WFC-O: 23.0381
WFC-N: 22.5046
WFC: 49.867
WEYS: 23.6079
WEX: 157.2006
WETF: 6.4591
WES: 49.7279
WERN: 33.014
WEN: 17.3226
WELL-I: 67.2576
WELL: 76.5676
WEC: 70.9432
WEBK: 19.4033
WEAT: 6.01
WEA: 12.71
WDRW: 30.5955
WDR: 16.8246
WDIV: 65.36
WDFC: 178.477
WDC: 42.8852
WDAY: 169.006
WD: 47.6938
WCN: 81.1874
WCHN: 16.8933
WCG: 275.2696
WCFB: 5.5666
WCC: 53.4524
WBT: 13.7981
WBS-F: 22.69
WBS: 56.0389
WBK: 18.1712
WBIY: 15.8999
WBIR: 15.4666
WBII: 16.1333
WBIG: 15.5599
WBID: 20.95
WBIB: 21.24
WBC: 112.9436
WBAI: 14.3123
WBA: 71.5766
WB: 58.147
WATT: 7.3618
WAT: 229.8209
WASH: 51.6241
WAL: 45.5689
WAIR: 8.0626
WAGE: 30.6939
WAFD: 29.2078
WABC: 62.9339
WAB: 68.5835
WAAS: 20.98
W: 107.4809
VZA: 25.7012
VZ: 53.1736
VYMI: 51.4692
VYM: 81.6335
VYGR: 10.4791
VXZB: 20.2113
VXXB: 38.2083
VXUS: 50.3101
VXRT: 1.8231
VXF: 109.3033
VWOB: 76.3892
VWO: 40.7009
VVV: 22.3744
VVUS: 4.7203
VVR: 3.344
VVPR: 0.6466
VVI: 51.4163
VVC: 72.0694
VV: 122.0443
VUZI: 4.0404
VUSE: 30.5733
VUG: 143.3898
VTWV: 74.5712
VTWO: 117.6004
VTWG: 133.4773
VTVT: 2.7047
VTV: 103.4451
VTSI: 3.8017
VTR: 63.9361
VTNR: 1.271
VTN: 12.63
VTL: 0.1953
VTIP: 48.045
VTI: 136.1174
VTHR: 116.902
VTGN: 1.5321
VTEB: 50.8417
VTC: 75.1725
VTA: 10.7003
VT: 69.7056
VSTO: 10.2609
VSTM: 3.1052
VST: 24.8605
VSS: 100.6381
VSMV: 28.1233
VSM: 37.0515
VSLR: 4.0181
VSI: 4.5049
VSH: 19.0083
VSGX: 31.8266
VSEC: 32.2807
VSAT: 61.3846
VRTX: 185.49
VRTV: 33.0419
VRTU: 47.6497
VRTSP: 66.5285
VRTS: 87.6664
VRSN: 165.6274
VRSK: 116.8175
VRS: 24.7154
VRRM: 10.2487
VRP: 22.3786
VRNT: 46.8865
VRNS: 57.3818
VRNA: 3.9839
VRML: 0.6853
VRIG: 20.995
VREX: 28.0056
VRCA: 11.9076
VRAY: 6.9207
VRA: 8.9392
VPV: 12.0451
VPU: 119.3741
VPL: 64.4646
VPG: 32.1342
VOYA: 45.8245
VOXX: 5.2579
VOX: 78.2614
VOT: 130.7476
VOOV: 104.4101
VOOG: 137.5363
VOO: 244.0024
VONV: 103.4679
VONG: 143.1914
VONE: 121.7679
VOE: 103.2785
VOD: 17.8339
VOC: 4.2755
VO: 150.349
VNTR: 4.5923
VNQI: 56.827
VNQ: 82.342
VNOM: 30.4134
VNO-M: 15.1533
VNO-L: 21.3263
VNO: 68.5087
VNM: 15.7481
VNLA: 49.344
VNET: 8.7157
VNE: 29.2632
VNDA: 28.3296
VNCE: 11.6079
VMW: 145.8
VMOT: 16.7666
VMO: 11.5461
VMI: 125.7327
VMC: 102.1845
VMBS: 51.6627
VLYPP: 24.3544
VLYPO: 22.254
VLY: 10.2641
VLUE: 78.4717
VLT: 13.7657
VLRX: 0.3986
VLRS: 7.4457
VLO: 82.2902
VLGEA: 26.6163
VKTXW: 4.3599
VKTX: 8.0204
VKQ: 11.7766
VKI: 8.9508
VJET: 1.3866
VIXY: 31.4101
VIXM: 22.4469
VIVO: 16.0362
VIVE: 1.189
VIV: 12.9053
VISI: 2.4666
VIS: 119.7817
VIRT: 25.4331
VIRC: 2.8466
VIPS: 7.4671
VIOV: 116.4129
VIOT: 6.1409
VIOO: 127.0724
VIIX: 16.1728
VIGI: 60.7832
VIG: 102.9472
VIDI: 16.3333
VICR: 40.1735
VICL: 0.9552
VICI: 21.4766
VIAV: 10.7713
VIAB: 28.3824
VIA: 32.6415
VHT: 166.382
VHI: 3.2441
VHC: 4.8638
VGZ: 0.4427
VGT: 177.5643
VGSH: 60.113
VGR: 10.521
VGM: 7.9999
VGLT: 74.3447
VGK: 51.5801
VGIT: 63.3878
VGI: 11.5857
VG: 9.0274
VFMV: 52.5599
VFMF: 48.2733
VFH: 64.8644
VFC: 83.8874
VEU: 48.5295
VET: 23.9223
VERU: 1.4856
VERI: 5.4142
VER-F: 16.7933
VER: 8.0267
VEON: 2.4648
VEGI: 18.7666
VEEV: 107.0425
VEDL: 11.0711
VECO: 9.8392
VEC: 24.0927
VEACW: 0.45
VEAC: 10.1332
VEA: 39.5726
VDE: 85.0202
VDC: 135.5138
VCYT: 17.5925
VCV: 10.9664
VCTR: 10.5728
VCSH: 78.6468
VCRA: 39.7613
VCR: 162.8286
VCNX: 3.3666
VCLT: 87.2058
VCIT: 84.3334
VCF: 9.1999
VCEL: 16.6463
VC: 75.0019
VBTX: 26.2569
VBR: 125.6291
VBND: 47.67
VBLT: 1.3056
VBK: 165.8621
VBIV: 1.6369
VBFC: 22.8066
VBF: 17.61
VB: 142.6276
VAW: 119.4313
VAR: 131.2888
VAPO: 16.4767
VALU: 14.0931
VALQ: 25.1466
VALE: 12.3542
VAC: 87.2862
V: 136.2502
UZC: 16.6266
UZB: 22.2055
UZA: 24.5266
UYM: 36.3466
UYG: 34.431
UXIN: 3.4824
UWT: 14.1251
UWN: 1.6466
UWM: 62.1029
UVXY: 59.1615
UVV: 57.242
UVSP: 23.7516
UVE: 37.8234
UUUU+: 0.8666
UUUU: 2.89
UUU: 1.191
UUP: 25.4783
UTX: 118.4108
UTSL: 27.0536
UTSI: 3.3995
UTMD: 60.6733
UTL: 48.4005
UTI: 3.3683
UTHR: 115.5134
UTG: 30.2462
UTF: 22.9503
UTES: 22.8799
USX: 7.3428
USWSW: 0.67
USWS: 6.8534
USVM: 33.0666
UST: 36.9599
USRT: 36.7211
USPH: 106.3565
USOU: 25.737
USOI: 21.1785
USOD: 6.5686
USO: 11.4144
USNA: 115.7274
USMV: 54.6513
USMC: 17.5199
USM: 55.9415
USLV: 79.5214
USLB: 20.2808
USL: 13.8599
USIG: 45.6183
USHY: 31.7599
USG: 43.1238
USFR: 21.5568
USFD: 34.3072
USEQ: 17.4266
USEG: 0.8873
USDU: 17.9399
USDP: 10.7507
USD: 24.2121
USCR: 37.2641
USCI: 32.2838
USB-P: 23.8093
USB-O: 22.6324
USB-M: 27.4597
USB-H: 19.0538
USB: 51.0077
USAU: 1.0057
USAT: 5.6248
USAS: 1.6054
USAP: 18.0349
USAK: 18.4102
USAC: 15.0951
USA: 5.7241
URTY: 64.119
URTH: 81.2417
UROV: 8.5508
URI: 123.6818
URGN: 40.5035
URG: 0.6298
URE: 67.84
URBN: 32.0289
URA: 12.6388
UQM: 1.6496
UPWK: 18.9148
UPV: 28.3266
UPS: 100.7544
UPRO: 40.9066
UPLD: 29.6262
UPL: 0.7579
