SampleOutput/sample_vwap_5.txt
XBUY: 16.5865
NRGX: 20.4506
CFG-D: 25.1019
ZYNE: 5.0596
ZYME: 15.2389
ZXZZT: 6.6666
ZVZZT: 9.9888
ZUO: 21.2239
ZUMZ: 24.9209
ZTS: 85.2219
ZTR: 9.7628
ZTO: 16.9557
ZSL: 35.2948
ZSAN: 2.1141
ZS: 45.4288
ZROZ: 74.7999
ZOM: 0.6443
ZNH: 32.3161
ZNGA: 4.4831
ZN: 0.4811
ZMLP: 9.0533
ZLAB: 26.8923
ZKIN: 1.5452
ZJZZT: 6.6666
ZIXI: 7.4943
ZIV: 66.5166
ZIOP: 2.0551
ZIONW: 10.7799
ZION: 48.3005
ZGNX: 41.6233
ZG: 32.8109
ZFGN: 4.2292
ZF: 8.7571
ZEUS: 18.6256
ZEN: 65.2432
ZEAL: 14.3166
ZDGE: 1.2933
ZBRA: 170.7222
ZBIO: 15.9775
ZBH: 107.2961
ZB-G: 26.84
ZAYO: 26.6962
ZAGG: 11.1714
Z: 33.0584
YYY: 17.2537
YY: 67.158
YVR: 1.5666
YUMC: 35.7292
YUMA: 0.1136
YUM: 93.1914
YTRA: 5.1022
YTEN: 0.7225
YRIV: 2.0739
YRD: 10.9679
YRCW: 5.7727
YPF: 15.7255
YORW: 31.67
YOGA: 0.5175
YNDX: 32.8661
YMLP: 19.35
YMLI: 8.2466
YMAB: 19.6775
YLDE: 18.3266
YLCO: 8.1399
YINN: 21.3311
YIN: 6.9446
YI: 8.6272
YGYI: 7.3371
YEXT: 14.9592
YETI: 16.7341
YELP: 36.0924
YCS: 49.4224
YANG: 52.7716
Y: 622.4739
XYL: 70.525
XYF: 5.36
XXII: 2.2768
XWEB: 84.9333
XTN: 39.6432
XTL: 65.0421
XT: 35.5906
XSW: 72.4896
XSPA: 0.1826
XSOE: 18.4399
XSLV: 45.6361
XSD: 68.9045
XRX: 27.7999
XRT: 43.945
XRLV: 22.7399
XRAY: 41.115
XPP: 65.3692
XPO: 61.4951
XPL: 0.184
XPH: 38.4567
XPER: 21.038
XOP: 30.514
XONE: 8.3509
XON: 7.4797
XOMA: 11.9765
XOM: 71.8378
XOG: 4.0673
XNTK: 57.0587
XNET: 3.4054
XNCR: 32.4788
XMLV: 41.4519
XME: 29.9678
XLY: 106.8186
XLV: 88.7701
XLU: 53.4131
XLRN: 39.9052
XLRE: 33.8926
XLP: 52.198
XLNX: 111.1341
XLK: 65.5084
XLI: 70.7693
XLG: 168.2985
XLF: 25.8469
XLE: 62.8604
XLC: 43.7512
XLB: 53.8411
XKST: 26.5
XITK: 92.5633
XIN: 4.7544
XHS: 45.6399
XHR: 18.6316
XHE: 71.8581
XHB: 35.5631
XGTI: 0.3699
XFLT: 8.4193
XES: 10.8763
XERS: 15.0003
XENT: 28.8698
XENE: 7.9256
XELB: 0.8133
XELA: 3.5994
XEL: 50.8854
XEC: 75.7623
XCEM: 17.2466
XBIT: 6.4412
XBIO: 2.1381
XBI: 80.5389
XAR: 88.5505
XAN: 10.5098
X: 22.1442
WYY: 0.4399
WYNN: 119.6733
WYND: 42.2746
WY: 26.0952
WWW: 33.87
WWR: 0.1423
WWE: 81.9372
WWD: 85.798
WVVIP: 3.0799
WVVI: 4.7066
WVFC: 9.6733
WVE: 35.4476
WUBA: 61.0658
WU: 18.2439
WTW: 31.9334
WTTR: 8.573
WTS: 73.1056
WTRH: 12.1637
WTR: 34.2277
WTMF: 25.5999
WTM: 893.4132
WTIU: 13.9254
WTID: 9.605
WTI: 5.0623
WTFCM: 18.5165
WTFC: 72.5782
WTER: 3.5008
WTBA: 21.6095
WSTL: 1.8205
WST: 105.475
WSR: 14.2908
WSO: 146.1622
WSM: 52.4306
WSFS: 41.9695
WSC: 10.1194
WSBF: 16.6831
WSBC: 41.492
WRTC: 2.8115
WRN: 0.7176
WRLSR: 0.2539
WRLS: 10.2
WRLD: 110.343
WRK: 41.266
WRI: 28.4174
WRE: 25.1396
WRD: 17.1461
WRB-E: 23.9759
WRB-D: 16.3299
WRB-C: 25.2104
WRB-B: 24.5272
WRB: 77.0062
WPX: 12.2533
WPS: 35.7751
WPRT: 1.4823
WPP: 57.699
WPM: 20.212
WPG-H: 10.4999
WPG: 5.7514
WPC: 73.9239
WP: 83.6585
WOW: 7.2407
WOR: 36.6467
WOOD: 66.0143
WNS: 48.9154
WNEB: 9.2846
WNC: 13.9465
WMT: 94.8809
WMS: 25.0134
WMK: 47.693
WMGIZ: 0.0046
WMGI: 29.6861
WMC: 9.577
WMB: 26.852
WM: 94.4742
WLTW: 159.8178
WLL: 28.6811
WLKP: 23.3877
WLK: 76.0235
WLH: 12.3097
WLFC: 30.2161
WLDN: 32.0291
WKHS: 0.8857
WK: 39.2058
WIX: 105.4712
WIW: 10.4946
WIT: 5.4814
WISA: 2.3751
WIRE: 52.5754
WIP: 35.9197
WINS: 23.7696
WING: 66.1748
WINA: 152.8742
WIN: 2.8556
WILC: 5.4266
WIL: 42.9666
WIFI: 22.7606
WIA: 10.9318
WHR: 130.883
WHLRW: 0.0066
WHLRP: 10.2696
WHLRD: 11.8366
WHLR: 1.6621
WHLM: 3.4999
WHG: 36.1209
WHF: 13.4468
WHD: 32.3936
WH: 49.6053
WGP: 32.6133
WGO: 29.3494
WFT: 0.6407
WFHY: 32.9333
WFE-A: 22.8599
WFC-Y: 16.6666
WFC-X: 22.3759
WFC-W: 23.5535
WFC-V: 25.8143
WFC-T: 17.1933
WFC-R: 18.4815
WFC-Q: 25.3742
WFC-P: 21.8105
WFC-O: 23.0381
WFC-N: 21.5889
WFC: 49.8776
WEYS: 23.857
WEX: 157.2548
WETF: 6.4658
WES: 49.7891
WERN: 33.0441
WEN: 17.3165
WELL-I: 67.2925
WELL: 76.5541
WEC: 70.9459
WEBK: 19.4033
WEAT: 6.01
WEA: 12.4629
WDRW: 30.5955
WDR: 16.8231
WDIV: 65.36
WDFC: 178.3545
WDC: 42.8902
WDAY: 169.1505
WD: 47.6958
WCN: 81.2232
WCHN: 16.8933
WCG: 275.1942
WCFB: 5.5666
WCC: 53.4752
WBT: 13.8037
WBS-F: 22.69
WBS: 56.0014
WBK: 18.1756
WBIY: 15.8999
WBIR: 15.4666
WBII: 16.1333
WBIH: 21.9733
WBIG: 15.5599
WBID: 20.95
WBIB: 21.24
WBC: 112.9099
WBAI: 14.3018
WBA: 71.5633
WB: 58.1648
WATT: 7.3576
WAT: 229.9106
WASH: 51.6268
WAL: 45.5648
WAIR: 8.0788
WAGE: 30.7176
WAFD: 29.1937
WABC: 62.9022
WAB: 68.4593
WAAS: 20.9784
W: 107.4808
VZA: 25.3286
VZ: 53.1901
VYMI: 53.8612
VYM: 81.6192
VYGR: 10.4979
VXZB: 20.2113
VXXB: 38.1961
VXUS: 50.311
VXRT: 1.8231
VXF: 109.3315
VWOB: 76.3893
VWO: 40.7176
VVV: 22.3659
VVUS: 4.7187
VVR: 3.7135
VVPR: 0.6466
VVI: 51.4163
VVC: 72.2287
VV: 122.0474
VUZI: 4.0368
VUSE: 30.5733
VUG: 143.4415
VTWV: 74.5712
VTWO: 117.6077
VTWG: 133.4773
VTVT: 2.7168
VTV: 103.4486
VTSI: 3.8017
VTR: 63.8866
VTNR: 1.2722
VTN: 12.6228
VTL: 0.1948
VTIP: 48.045
VTI: 136.151
VTHR: 116.902
VTGN: 1.5322
VTEB: 50.9619
VTC: 75.1725
VTA: 10.6999
VT: 69.7235
VSTO: 10.311
VSTM: 3.1079
VST: 24.8735
VSS: 100.6399
VSMV: 28.1027
VSM: 37.0047
VSLR: 4.0112
VSI: 4.5694
VSH: 19.0332
VSGX: 31.8266
VSEC: 32.1121
VSAT: 61.3701
VRTX: 185.5834
VRTV: 33.0424
VRTU: 47.6318
VRTSP: 76.0257
VRTS: 87.4801
VRSN: 165.7407
VRSK: 116.8363
VRS: 24.6994
VRRM: 10.2527
VRP: 22.4785
VRNT: 46.9009
VRNS: 57.3896
VRNA: 4.3914
VRML: 0.6854
VRIG: 20.995
VREX: 27.9819
VRCA: 11.9076
VRAY: 6.9187
VRA: 8.9427
VPV: 12.0451
VPU: 119.2873
VPL: 64.4689
VPG: 31.9562
VOYA: 45.8497
VOXX: 5.1822
VOX: 78.277
VOT: 130.7978
VOOV: 104.4526
VOOG: 138.6663
VOO: 244.0073
VONV: 103.4639
VONG: 143.2338
VONE: 121.8037
VOE: 103.286
VOD: 17.8318
VOC: 3.6181
VO: 150.3667
VNTR: 4.6027
VNRX: 2.5433
VNQI: 56.8352
VNQ: 82.3429
VNOM: 30.4224
VNO-M: 15.1533
VNO-L: 21.3263
VNO: 68.5493
VNM: 15.7493
VNLA: 49.344
VNET: 8.7105
VNE: 29.2451
VNDA: 28.3352
VNCE: 11.6217
VMW: 145.8277
VMOT: 16.7666
VMO: 11.5919
VMM: 12.17
VMI: 125.9698
VMC: 101.8453
VMBS: 51.6613
VLYPP: 24.3751
VLYPO: 22.5417
VLY: 10.2667
VLUE: 78.4771
VLT: 13.7657
VLRX: 0.3987
VLRS: 7.4278
VLO: 82.3485
VLGEA: 25.9053
VKTXW: 4.3599
VKTX: 8.0371
VKQ: 11.7646
VKI: 8.9508
VJET: 1.3866
VIXY: 31.402
VIXM: 22.4469
VIVO: 16.0314
VIVE: 1.1855
VIV: 12.9056
VISI: 2.4666
VIS: 119.7817
VIRT: 25.4515
VIRC: 2.8231
VIPS: 7.4681
VIOV: 116.4129
VIOT: 6.9244
VIOO: 127.0724
VIOG: 99.3866
VIIX: 16.1636
VIGI: 60.7824
VIG: 102.953
VIDI: 16.3553
VICR: 40.2412
VICL: 0.9552
VICI: 21.4685
VIAV: 10.7675
VIAB: 28.3841
VIA: 32.7354
VHT: 166.3853
VHI: 3.244
VHC: 4.8724
VGZ: 0.4427
VGT: 177.5813
VGSH: 60.1139
VGR: 10.5277
VGM: 10.2056
VGLT: 74.3439
VGK: 51.5821
VGIT: 63.3877
VGI: 11.5857
VG: 9.031
VFMV: 52.5599
VFMF: 48.2733
VFH: 64.8761
VFC: 83.9356
VEU: 48.5281
VET: 23.9427
VERU: 1.4856
VERI: 5.4132
VER-F: 16.7933
VER: 8.021
VEON: 2.4639
VEGI: 18.8058
VEEV: 107.0416
VEDL: 11.0677
VECO: 9.8242
VEC: 24.1388
VEACW: 0.4417
VEAC: 10.1332
VEA: 39.5796
VDE: 85.0229
VDC: 135.473
VCYT: 17.5711
VCV: 11.1034
VCTR: 10.5693
VCSH: 78.6468
VCRA: 39.7564
VCR: 161.7853
VCNX: 3.3666
VCLT: 87.2143
VCIT: 84.3334
VCF: 9.1999
VCEL: 16.609
VC: 75.0691
VBTX: 26.317
VBR: 125.6837
VBND: 47.67
VBLT: 1.3027
VBK: 165.8763
VBIV: 1.6379
VBFC: 22.8066
VBF: 17.6067
VB: 144.164
VAW: 119.4267
VAR: 131.2274
VAPO: 16.4713
VALU: 14.0931
VALQ: 25.1869
VALE: 12.359
VAC: 87.3212
V: 136.2776
UZC: 16.6266
UZB: 22.2055
UZA: 24.5266
UYM: 36.3466
UYG: 34.431
UXIN: 3.4807
UWT: 14.1374
UWN: 2.3824
UWM: 62.1092
UVXY: 59.1092
UVV: 57.2986
UVSP: 23.7454
UVE: 37.768
UUUU+: 0.8666
UUUU: 2.8862
UUU: 1.191
UUP: 25.4784
UTX: 118.4618
UTSL: 26.497
UTSI: 3.402
UTMD: 88.991
UTL: 48.4983
UTI: 3.3728
UTHR: 115.5575
UTG: 30.3115
UTF: 22.9524
UTES: 22.8799
USX: 7.3588
USWSW: 0.67
USWS: 7.2325
USVM: 33.0666
UST: 36.9599
USRT: 36.7211
USPH: 106.2483
USOU: 25.737
USOI: 21.1785
USOD: 6.5686
USO: 11.4172
USNA: 115.6847
USMV: 54.6549
USMF: 18.5133
USMC: 17.5199
USM: 55.961
USLV: 79.4975
USLB: 28.3746
USL: 13.9053
USIG: 51.0623
USHY: 31.7658
USG: 43.1231
USFR: 21.5568
USFD: 34.2864
USEQ: 17.4266
USEG: 0.8873
USDU: 17.9399
USDP: 10.7507
USD: 28.511
USCR: 37.2931
USCI: 32.2838
USB-P: 23.9302
USB-O: 22.6324
USB-M: 26.2101
USB-H: 19.415
USB: 51.0053
USAU: 1.0049
USAT: 5.6406
USAS: 1.6054
USAP: 17.8584
USAK: 18.3944
USAC: 15.0994
USA: 5.7306
URTY: 64.1226
URTH: 81.2417
UROV: 8.5497
